Workbook
Name _GoBack: 填表说明!#REF!

Sheet 填表说明
A2: 一、 填写规则
A3: 1. “ICT类项目财务价值评估表”共3部分，项目概况、基础数据和效益评估。该表格有自动计算公式，只需填写标黄部分的单元格，严禁修改橙色内容，金额数据单位为万元。
A4: 2. 首先填写项目基本信息
A5: 3.在“基础数据”部分，根据项目情况填写投资、收入、成本细项含税金额及对应税率，税率为经验参考值，可根据项目实际情况进行修正。若某单项指标可能涉及到多种增值税率，在表中无法准确计算出不含税的数据，可直接将结果填写在表中相应位置，模板自动计算不含税金额。
A6: 4. 在“经济效益评估”中，填写的数据均为不含税金额 （1）“初始项目投资”即使用ICT切块资金金额，按照实际使用投资按年度分别填写； （2）“收入”包含该项目直接收益的各项业务年收入累计值，按照实际收入协议期每年列支金额分别填写； （3）“支出”包含业务维护成本和IT建设成本，业务成本即使用合作模式和购销模式使用的成本费用； （4）“终端及其他营销资源投入”包含用于该项目营销成本、终端、酬金等其它营销资源等。 （5）对填列金额与基础数据在M列设置校验关系，校验结果应为“TRUE”
A7: 5.折旧和摊销计算表见附表，需填列各类资产投资额及投产月份，表格自动计算折旧额。
A8: 二、 重要指标说明
A9: 1. 财务净现值率=净现值/项目总投入现值*100%，净现值为建设期及生产期各年净现金流量现值合计值，总投入现值为建设及生产期内的建设投资及成本支出的累计现值。
A10: 2.静态投资回收期=不考虑时间价值，累计净现金流量开始出现正值的年份数-1+上一年累计净现金流量的绝对值/出现正值年份的净现金流量。
A11: 3. 动态投资回收期=考虑时间价值，累计净现值开始出现正值的年份数-1+上一年累计净现值的绝对值/出现正值年份的净现值。
A12: 4. 折现率参考通信行业折现率，本表中取国资委给定的公司加权平均资本成本（目前为5.5%）。
A13: 5. 折旧及摊销费，根据各年项目投资计算各年的折旧费，采用平均年限法计算折旧，按照中国移动固定资产目录，光缆和管道按照10年、传输设备7年、服务器5年计算折旧。
... A15: 7. 在本表中仅考虑项目建设开展过程中的直接成本，因间接成本项较多，难以准确计算，且在计算效益时影响相对较小，故在本表中未纳入计算，但应对投资效益从严把控。

Sheet 政企项目投资效益评估表
A1: ICT类项目财务价值评估表
A2: 本模板适用于合作模式、投资模式和其它模式投资部分，并适用于以上各模式混合的项目
A3: 项目概况 | B3: 项目名称 | D3: 综合布线及无线网络建设项目 | F3: 业主单位 | G3: 有研亿金新材料（山东）有限公司
B4: 项目年限 | D4: 1 | F4: 预计投资金额 | G4: =H31-J31-K31 -> 0 | H4: 预计收入金额 | I4: =H17-J17-K17 -> 16.772251 | J4: 预计成本金额 | K4: =H49-J49-K49 -> 14.955802
A6: 基础数据 | B6: 明细项目（单位：万元） | F6: CT（含税） | G6: IT（含税） | H6: 合同金额（含税） | I6: 税率 | J6: CT增值税 | K6: IT增值税 | L6: 备注
A7: 直接收入 | B7: 项目收入 （万元） | C7: 1）集成费 | G7: 7.91 | H7: =F7+G7 -> 7.91 | I7: 0.06 | J7: =F7/(1+I7)*I7 -> 0 | K7: =G7/(1+I7)*I7 -> 0.44773585 | L7: 根据客户的需求，将硬件、网络、数据库及相应的应用软件进行优化整合，提供全面系统解决方案而向客户收取的系统集成费，主要包括项目集成方案的咨询、设计、软硬件安装、通信工程服务、调测开通等项目实施服务费，为一次性费用。
C8: 2）维保费 | H8: =F8+G8 -> 0 | I8: 0.06 | J8: =F8/(1+I8)*I8 -> 0 | K8: =G8/(1+I8)*I8 -> 0 | L8: 指公司在ICT项目建成后，因提供后续维护保障服务而向客户收取的维保费。
C9: 3）通信业务收入（基础电信服务） | H9: =F9+G9 -> 0 | I9: 0.09 | J9: =F9/(1+I9)*I9 -> 0 | K9: =G9/(1+I9)*I9 -> 0 | L9: 指ICT项目建成后客户使用ICT业务而产生的语音、短彩信、无线上网、专线、物联网等通信服务费。
C10: 4）通信业务收入（增值电信服务） | H10: =F10+G10 -> 0 | I10: 0.06 | J10: =F10/(1+I10)*I10 -> 0 | K10: =G10/(1+I10)*I10 -> 0 | L10: 指ICT项目建成后客户使用ICT业务而产生的互联网业务等通信服务费。
C11: 5）功能费收入 | H11: =F11+G11 -> 0 | I11: 0.06 | J11: =F11/(1+I11)*I11 -> 0 | K11: =G11/(1+I11)*I11 -> 0 | L11: 指标准化集团信息化产品按月产生的功能费收入，如视频监控等。
C12: 6）设备租赁收入 | H12: =F12+G12 -> 0 | I12: 0.13 | J12: =F12/(1+I12)*I12 -> 0 | K12: =G12/(1+I12)*I12 -> 0 | L12: 指ICT项目中出租设备产生的收入。
C13: 7）设备（含第三方软件）销售收入 | H13: =F13+G13 -> 0 | I13: 0.13 | J13: =F13/(1+I13)*I13 -> 0 | K13: =G13/(1+I13)*I13 -> 0 | L13: 指ICT项目中销售设备及相关第三方软件产生的收入。
C14: 8）终端（含第三方软件）销售收入 | H14: =F14+G14 -> 0 | I14: 0.13 | J14: =F14/(1+I14)*I14 -> 0 | K14: =G14/(1+I14)*I14 -> 0 | L14: 指ICT项目中销售终端及相关第三方软件产生的收入。
C15: 9）终端租赁收入 | H15: =F15+G15 -> 0 | I15: 0.13 | J15: =F15/(1+I15)*I15 -> 0 | K15: =G15/(1+I15)*I15 -> 0 | L15: 指ICT项目中出租终端产生的收入。
C16: 10）其他收入 | G16: 10.147886 | H16: =F16+G16 -> 10.147886 | I16: 0.09 | J16: =F16/(1+I16)*I16 -> 0 | K16: =G16/(1+I16)*I16 -> 0.83789884 | L16: 指项目带来的其他收入 | P16: 0.196 | Q16: 9.95 | R16: =P16+Q16 -> 10.146
B17: 项目收入小计 | F17: =SUM(F7:F16) -> 0 | G17: =SUM(G7:G16) -> 18.057886 | H17: =F17+G17 -> 18.057886 | J17: =SUM(J7:J16) -> 0 | K17: =SUM(K7:K16) -> 1.2856347
A18: 直接支出 | B18: 投资 （万元） | C18: 其中：1、平台类投资 | F18: =SUM(F19:F24) -> 0 | G18: =SUM(G19:G24) -> 0 | H18: =F18+G18 -> 0 | J18: =SUM(J19:J24) -> 0 | K18: =SUM(K19:K24) -> 0
C19: 1）硬件设备类投资 | H19: =F19+G19 -> 0 | I19: 0.13 | J19: =F19/(1+I19)*I19 -> 0 | K19: =G19/(1+I19)*I19 -> 0 | L19: 指项目建设完成后资产归属于我公司的平台设备采购投资。
C20: 2）定制软件类投资 | H20: =F20+G20 -> 0 | I20: 0.06 | J20: =F20/(1+I20)*I20 -> 0 | K20: =G20/(1+I20)*I20 -> 0 | L20: 指项目建设完成后资产归属于我公司的平台定制软件采购投资。
C21: 3）集成服务费 | H21: =F21+G21 -> 0 | I21: 0.06 | J21: =F21/(1+I21)*I21 -> 0 | K21: =G21/(1+I21)*I21 -> 0 | L21: 指资产归属于我公司的平台软硬件设备集成费用。
C22: 4）工程配套费 | H22: =F22+G22 -> 0 | J22: =F22/(1+I22)*I22 -> 0 | K22: =G22/(1+I22)*I22 -> 0 | L22: 指资产归属我公司的平台软硬件设备设所需的线缆、走线架等配套费用
C23: 5）建安费用 | H23: =F23+G23 -> 0 | J23: =F23/(1+I23)*I23 -> 0 | K23: =G23/(1+I23)*I23 -> 0 | L23: 指资产归属我公司的平台软硬件设备建设安装工程费。
C24: 6）设计监理费 | H24: =F24+G24 -> 0 | I24: 0.06 | J24: =F24/(1+I24)*I24 -> 0 | K24: =G24/(1+I24)*I24 -> 0 | L24: 指项目建设完成后资产归属于我公司投资项目相关的设计、可研及监理费用。
C25: 2、传输网络配套投资 | F25: =SUM(F26:F28) -> 0 | G25: =SUM(G26:G28) -> 0 | H25: =F25+G25 -> 0 | J25: =SUM(J26:J28) -> 0 | K25: =SUM(K26:K28) -> 0
C26: 1）管道类投资 | H26: =F26+G26 -> 0 | I26: 0.13 | J26: =F26/(1+I26)*I26 -> 0 | K26: =G26/(1+I26)*I26 -> 0 | L26: 指项目建设末端接入需要的管道、杆路等主材、配套和工程服务投资。
C27: 2）光缆类投资 | H27: =F27+G27 -> 0 | I27: 0.13 | J27: =F27/(1+I27)*I27 -> 0 | K27: =G27/(1+I27)*I27 -> 0 | L27: 指项目建设末端接入需要的光缆等主材、配套和工程服务投资。 | P27: =Q56 -> 0.081225634
C28: 3）设备类投资 | H28: =F28+G28 -> 0 | I28: 0.13 | J28: =F28/(1+I28)*I28 -> 0 | K28: =G28/(1+I28)*I28 -> 0 | L28: 指项目建设末端接入需要的SDH/PTN/OTN/GPON/微波以及MSAP，小型化PTN、光收发、协转、OLP、IMS接入设备等主设备、配套和工程服务投资。 | P28: =Q57 -> 0.088406508
C29: 3、其他网络配套投资 | F29: =SUM(F30) -> 0 | G29: =SUM(G30) -> 0 | H29: =F29+G29 -> 0 | J29: =SUM(J30) -> 0 | K29: =SUM(K30) -> 0 | L29: 项目建设中涉及的其他网络配套投资。
C30: 其他建设费用（如有需按税率区分） | H30: =F30+G30 -> 0 | J30: =F30/(1+I30)*I30 -> 0 | K30: =G30/(1+I30)*I30 -> 0 | L30: 项目建设中涉及的其他网络配套投资。
B31: 投资小计 | F31: =F18+F25+F29 -> 0 | G31: =G18+G25+G29 -> 0 | H31: =F31+G31 -> 0 | J31: =J18+J25+J29 -> 0 | K31: =K18+K25+K29 -> 0
B32: 成本 （万元） | C32: 其中：1、建设费用 | D32: 维护/投入比 | E32: =H32/SUM(H18:H30) -> #DIV/0! | F32: =SUM(F33:F37) -> 0 | G32: =SUM(G33:G37) -> 16.1019 | H32: =F32+G32 -> 16.1019 | J32: =SUM(J33:J37) -> 0 | K32: =SUM(K33:K37) -> 1.1460977
C33: 1）设备采购支出 | H33: =F33+G33 -> 0 | I33: 0.13 | J33: =F33/(1+I33)*I33 -> 0 | K33: =G33/(1+I33)*I33 -> 0 | L33: 指项目建设完成后资产不归属于我公司的平台设备采购支出。
C34: 2）集成建设费用 | G34: 7.064 | H34: =F34+G34 -> 7.064 | I34: 0.06 | J34: =F34/(1+I34)*I34 -> 0 | K34: =G34/(1+I34)*I34 -> 0.39984906 | L34: 根据客户的需求，将硬件、网络、数据库及相应的应用软件进行优化整合，提供全面系统解决方案所需的项目集成建设费用。
C35: 3）中标服务费 | H35: =F35+G35 -> 0 | I35: 0.06 | J35: =F35/(1+I35)*I35 -> 0 | K35: =G35/(1+I35)*I35 -> 0 | L35: 指招标代理机构接受委托，编制招标文件(包括编制资格预审文件和标底)，审查投标人资格，组织投标人查勘现场并答疑，组织开标、评标、定标,以及提供招标前期咨询、协调合同的签订等服务所收取的费用。
C36: 4）建安费用 | G36: 9.0379 | H36: =F36+G36 -> 9.0379 | I36: 0.09 | J36: =F36/(1+I36)*I36 -> 0 | K36: =G36/(1+I36)*I36 -> 0.74624862 | L36: 指建设安装工程费。 | P36: 0.1489 | Q36: 8.889 | R36: =P36+Q36 -> 9.0379
C37: 5）其他建设费用 | H37: =F37+G37 -> 0 | J37: =F37/(1+I37)*I37 -> 0 | K37: =G37/(1+I37)*I37 -> 0 | L37: 指项目建设过程中其他费用。
C38: 2、运行维护费用 | F38: =SUM(F39:F41) -> 0 | G38: =SUM(G39:G41) -> 0 | H38: =F38+G38 -> 0 | J38: =SUM(J39:J41) -> 0 | K38: =SUM(K39:K41) -> 0
C39: 1）维护费用 | H39: =F39+G39 -> 0 | I39: 0.06 | J39: =F39/(1+I39)*I39 -> 0 | K39: =G39/(1+I39)*I39 -> 0 | L39: 指项目在运营维护过程中发生的设备维护支出及费用。
C40: 2）设备更新费用 | H40: =F40+G40 -> 0 | I40: 0.13 | J40: =F40/(1+I40)*I40 -> 0 | K40: =G40/(1+I40)*I40 -> 0 | L40: 指项目在运行过程中设备更新发生的支出及费用。
C41: 3）其他运行费用（电费、耗材等） | H41: =F41+G41 -> 0 | J41: =F41/(1+I41)*I41 -> 0 | K41: =G41/(1+I41)*I41 -> 0 | L41: 指项目在运行过程中发生的其他运行费用，如电费、耗材、场租、水费等。
...

Sheet 折旧和摊销计算表
A1: 参考中国移动固定资产目录，平台类设备折旧年限为5年，传输网设备7年，光缆管道10年，软件类5年 | D1: 合计 | E1: 第一年 | F1: 第二年 | G1: 第三年 | H1: 第四年 | I1: 第五年 | J1: 第六年 | K1: 第七年 | L1: 第八年 | M1: 第九年 | N1: 第十年 | O1: 第十一年 | P1: 第十二年 | Q1: 第十三年 | R1: 第十四年 | S1: 第十五年 | T1: 第十六年 | U1: 第十七年 | V1: 第十八年 | W1: 第十九年 | X1: 第二十年
A2: 折旧及摊销 | B2: 总投资各年折旧及摊销 | D2: =SUM(E2:X2) -> 0 | E2: =E4+E20+E36+E52+E68 -> 0 | F2: =F4+F20+F36+F52+F68 -> 0 | G2: =G4+G20+G36+G52+G68 -> 0 | H2: =H4+H20+H36+H52+H68 -> 0 | I2: =I4+I20+I36+I52+I68 -> 0 | J2: =J4+J20+J36+J52+J68 -> 0 | K2: =K4+K20+K36+K52+K68 -> 0 | L2: =L4+L20+L36+L52+L68 -> 0 | ... X2: =X4+X20+X36+X52+X68 -> 0
B4: 平台类设备投资累计折旧 | D4: =SUM(E4:X4) -> 0 | E4: =SUM(E8:E18) -> 0 | F4: =SUM(F8:F18) -> 0 | G4: =SUM(G8:G18) -> 0 | H4: =SUM(H8:H18) -> 0 | I4: =SUM(I8:I18) -> 0 | J4: =SUM(J8:J18) -> 0 | K4: =SUM(K8:K18) -> 0 | L4: =SUM(L8:L18) -> 0 | ... X4: =SUM(X8:X18) -> 0
B5: 折旧年限 | C5: 5
B6: 当年投产月份 | E6: 0 | F6: 0 | G6: 0 | H6: 0 | I6: 0 | J6: 0 | K6: 0 | L6: 0 | M6: 0 | N6: 0 | O6: 0
B7: 各年平台类设备投资规模 | D7: =SUM(E7:O7) -> 0
B8: 第一年投资在各年的折旧 | D8: =SUM(E8:X8) -> 0 | E8: =F8*(1-E6/12) -> 0 | F8: =E7/C5 -> 0 | G8: =IF(SUM(E8:F8)<E7,IF((E7-SUM(E8:F8))<E7/C5,E7-SUM(E8:F8),E7/C5),0) -> 0 | H8: =IF(SUM(E8:G8)<E7,IF((E7-SUM(E8:G8))<E7/C5,E7-SUM(E8:G8),E7/C5),0) -> 0 | I8: =IF(SUM(E8:H8)<E7,IF((E7-SUM(E8:H8))<E7/C5,E7-SUM(E8:H8),E7/C5),0) -> 0 | J8: =IF(SUM(E8:I8)<E7,IF((E7-SUM(E8:I8))<E7/C5,E7-SUM(E8:I8),E7/C5),0) -> 0 | K8: =IF(SUM(E8:J8)<E7,IF((E7-SUM(E8:J8))<E7/C5,E7-SUM(E8:J8),E7/C5),0) -> 0 | L8: =IF(SUM(E8:K8)<E7,IF((E7-SUM(E8:K8))<E7/C5,E7-SUM(E8:K8),E7/C5),0) -> 0 | M8: =IF(SUM(E8:L8)<E7,IF((E7-SUM(E8:L8))<E7/C5,E7-SUM(E8:L8),E7/C5),0) -> 0 | N8: =IF(SUM(E8:M8)<E7,IF((E7-SUM(E8:M8))<E7/C5,E7-SUM(E8:M8),E7/C5),0) -> 0 | O8: =IF(SUM(E8:N8)<E7,IF((E7-SUM(E8:N8))<E7/C5,E7-SUM(E8:N8),E7/C5),0) -> 0 | P8: =IF(SUM(E8:O8)<E7,IF((E7-SUM(E8:O8))<E7/C5,E7-SUM(E8:O8),E7/C5),0) -> 0 | Q8: =IF(SUM(E8:P8)<E7,IF((E7-SUM(E8:P8))<E7/C5,E7-SUM(E8:P8),E7/C5),0) -> 0 | R8: =IF(SUM(E8:Q8)<E7,IF((E7-SUM(E8:Q8))<E7/C5,E7-SUM(E8:Q8),E7/C5),0) -> 0 | S8: =IF(SUM(E8:R8)<E7,IF((E7-SUM(E8:R8))<E7/C5,E7-SUM(E8:R8),E7/C5),0) -> 0 | T8: =IF(SUM(E8:S8)<E7,IF((E7-SUM(E8:S8))<E7/C5,E7-SUM(E8:S8),E7/C5),0) -> 0 | U8: =IF(SUM(E8:T8)<E7,IF((E7-SUM(E8:T8))<E7/C5,E7-SUM(E8:T8),E7/C5),0) -> 0 | V8: =IF(SUM(E8:U8)<E7,IF((E7-SUM(E8:U8))<E7/C5,E7-SUM(E8:U8),E7/C5),0) -> 0 | W8: =IF(SUM(E8:V8)<E7,IF((E7-SUM(E8:V8))<E7/C5,E7-SUM(E8:V8),E7/C5),0) -> 0 | X8: =IF(SUM(E8:W8)<E7,IF((E7-SUM(E8:W8))<E7/C5,E7-SUM(E8:W8),E7/C5),0) -> 0
B9: 第二年投资在各年的折旧 | D9: =SUM(E9:X9) -> 0 | F9: =G9*(1-F6/12) -> 0 | G9: =F7/C5 -> 0 | H9: =IF(SUM(E9:G9)<F7,IF((F7-SUM(E9:G9))<F7/C5,F7-SUM(E9:G9),F7/C5),0) -> 0 | I9: =IF(SUM(E9:H9)<F7,IF((F7-SUM(E9:H9))<F7/C5,F7-SUM(E9:H9),F7/C5),0) -> 0 | J9: =IF(SUM(E9:I9)<F7,IF((F7-SUM(E9:I9))<F7/C5,F7-SUM(E9:I9),F7/C5),0) -> 0 | K9: =IF(SUM(E9:J9)<F7,IF((F7-SUM(E9:J9))<F7/C5,F7-SUM(E9:J9),F7/C5),0) -> 0 | L9: =IF(SUM(E9:K9)<F7,IF((F7-SUM(E9:K9))<F7/C5,F7-SUM(E9:K9),F7/C5),0) -> 0 | M9: =IF(SUM(E9:L9)<F7,IF((F7-SUM(E9:L9))<F7/C5,F7-SUM(E9:L9),F7/C5),0) -> 0 | N9: =IF(SUM(E9:M9)<F7,IF((F7-SUM(E9:M9))<F7/C5,F7-SUM(E9:M9),F7/C5),0) -> 0 | O9: =IF(SUM(E9:N9)<F7,IF((F7-SUM(E9:N9))<F7/C5,F7-SUM(E9:N9),F7/C5),0) -> 0 | P9: =IF(SUM(E9:O9)<F7,IF((F7-SUM(E9:O9))<F7/C5,F7-SUM(E9:O9),F7/C5),0) -> 0 | Q9: =IF(SUM(E9:P9)<F7,IF((F7-SUM(E9:P9))<F7/C5,F7-SUM(E9:P9),F7/C5),0) -> 0 | R9: =IF(SUM(E9:Q9)<F7,IF((F7-SUM(E9:Q9))<F7/C5,F7-SUM(E9:Q9),F7/C5),0) -> 0 | S9: =IF(SUM(E9:R9)<F7,IF((F7-SUM(E9:R9))<F7/C5,F7-SUM(E9:R9),F7/C5),0) -> 0 | T9: =IF(SUM(E9:S9)<F7,IF((F7-SUM(E9:S9))<F7/C5,F7-SUM(E9:S9),F7/C5),0) -> 0 | U9: =IF(SUM(E9:T9)<F7,IF((F7-SUM(E9:T9))<F7/C5,F7-SUM(E9:T9),F7/C5),0) -> 0 | V9: =IF(SUM(E9:U9)<F7,IF((F7-SUM(E9:U9))<F7/C5,F7-SUM(E9:U9),F7/C5),0) -> 0 | W9: =IF(SUM(E9:V9)<F7,IF((F7-SUM(E9:V9))<F7/C5,F7-SUM(E9:V9),F7/C5),0) -> 0 | X9: =IF(SUM(E9:W9)<F7,IF((F7-SUM(E9:W9))<F7/C5,F7-SUM(E9:W9),F7/C5),0) -> 0
B10: 第三年投资在各年的折旧 | D10: =SUM(E10:X10) -> 0 | G10: =H10*(1-G6/12) -> 0 | H10: =G7/C5 -> 0 | I10: =IF(SUM(E10:H10)<G7,IF((G7-SUM(E10:H10))<G7/C5,G7-SUM(E10:H10),G7/C5),0) -> 0 | J10: =IF(SUM(E10:I10)<G7,IF((G7-SUM(E10:I10))<G7/C5,G7-SUM(E10:I10),G7/C5),0) -> 0 | K10: =IF(SUM(E10:J10)<G7,IF((G7-SUM(E10:J10))<G7/C5,G7-SUM(E10:J10),G7/C5),0) -> 0 | L10: =IF(SUM(E10:K10)<G7,IF((G7-SUM(E10:K10))<G7/C5,G7-SUM(E10:K10),G7/C5),0) -> 0 | M10: =IF(SUM(E10:L10)<G7,IF((G7-SUM(E10:L10))<G7/C5,G7-SUM(E10:L10),G7/C5),0) -> 0 | N10: =IF(SUM(E10:M10)<G7,IF((G7-SUM(E10:M10))<G7/C5,G7-SUM(E10:M10),G7/C5),0) -> 0 | O10: =IF(SUM(E10:N10)<G7,IF((G7-SUM(E10:N10))<G7/C5,G7-SUM(E10:N10),G7/C5),0) -> 0 | P10: =IF(SUM(E10:O10)<G7,IF((G7-SUM(E10:O10))<G7/C5,G7-SUM(E10:O10),G7/C5),0) -> 0 | Q10: =IF(SUM(E10:P10)<G7,IF((G7-SUM(E10:P10))<G7/C5,G7-SUM(E10:P10),G7/C5),0) -> 0 | R10: =IF(SUM(E10:Q10)<G7,IF((G7-SUM(E10:Q10))<G7/C5,G7-SUM(E10:Q10),G7/C5),0) -> 0 | S10: =IF(SUM(E10:R10)<G7,IF((G7-SUM(E10:R10))<G7/C5,G7-SUM(E10:R10),G7/C5),0) -> 0 | T10: =IF(SUM(E10:S10)<G7,IF((G7-SUM(E10:S10))<G7/C5,G7-SUM(E10:S10),G7/C5),0) -> 0 | U10: =IF(SUM(E10:T10)<G7,IF((G7-SUM(E10:T10))<G7/C5,G7-SUM(E10:T10),G7/C5),0) -> 0 | V10: =IF(SUM(E10:U10)<G7,IF((G7-SUM(E10:U10))<G7/C5,G7-SUM(E10:U10),G7/C5),0) -> 0 | W10: =IF(SUM(E10:V10)<G7,IF((G7-SUM(E10:V10))<G7/C5,G7-SUM(E10:V10),G7/C5),0) -> 0 | X10: =IF(SUM(E10:W10)<G7,IF((G7-SUM(E10:W10))<G7/C5,G7-SUM(E10:W10),G7/C5),0) -> 0
B11: 第四年投资在各年的折旧 | D11: =SUM(E11:X11) -> 0 | H11: =I11*(1-H6/12) -> 0 | I11: =H7/C5 -> 0 | J11: =IF(SUM(E11:I11)<H7,IF((H7-SUM(E11:I11))<H7/C5,H7-SUM(E11:I11),H7/C5),0) -> 0 | K11: =IF(SUM(E11:J11)<H7,IF((H7-SUM(E11:J11))<H7/C5,H7-SUM(E11:J11),H7/C5),0) -> 0 | L11: =IF(SUM(E11:K11)<H7,IF((H7-SUM(E11:K11))<H7/C5,H7-SUM(E11:K11),H7/C5),0) -> 0 | M11: =IF(SUM(E11:L11)<H7,IF((H7-SUM(E11:L11))<H7/C5,H7-SUM(E11:L11),H7/C5),0) -> 0 | N11: =IF(SUM(E11:M11)<H7,IF((H7-SUM(E11:M11))<H7/C5,H7-SUM(E11:M11),H7/C5),0) -> 0 | O11: =IF(SUM(E11:N11)<H7,IF((H7-SUM(E11:N11))<H7/C5,H7-SUM(E11:N11),H7/C5),0) -> 0 | P11: =IF(SUM(E11:O11)<H7,IF((H7-SUM(E11:O11))<H7/C5,H7-SUM(E11:O11),H7/C5),0) -> 0 | Q11: =IF(SUM(E11:P11)<H7,IF((H7-SUM(E11:P11))<H7/C5,H7-SUM(E11:P11),H7/C5),0) -> 0 | R11: =IF(SUM(E11:Q11)<H7,IF((H7-SUM(E11:Q11))<H7/C5,H7-SUM(E11:Q11),H7/C5),0) -> 0 | S11: =IF(SUM(E11:R11)<H7,IF((H7-SUM(E11:R11))<H7/C5,H7-SUM(E11:R11),H7/C5),0) -> 0 | T11: =IF(SUM(E11:S11)<H7,IF((H7-SUM(E11:S11))<H7/C5,H7-SUM(E11:S11),H7/C5),0) -> 0 | U11: =IF(SUM(E11:T11)<H7,IF((H7-SUM(E11:T11))<H7/C5,H7-SUM(E11:T11),H7/C5),0) -> 0 | V11: =IF(SUM(E11:U11)<H7,IF((H7-SUM(E11:U11))<H7/C5,H7-SUM(E11:U11),H7/C5),0) -> 0 | W11: =IF(SUM(E11:V11)<H7,IF((H7-SUM(E11:V11))<H7/C5,H7-SUM(E11:V11),H7/C5),0) -> 0 | X11: =IF(SUM(E11:W11)<H7,IF((H7-SUM(E11:W11))<H7/C5,H7-SUM(E11:W11),H7/C5),0) -> 0
B12: 第五年投资在各年的折旧 | D12: =SUM(E12:X12) -> 0 | I12: =J12*(1-I6/12) -> 0 | J12: =I7/C5 -> 0 | K12: =IF(SUM(E12:J12)<I7,IF((I7-SUM(E12:J12))<I7/C5,I7-SUM(E12:J12),I7/C5),0) -> 0 | L12: =IF(SUM(E12:K12)<I7,IF((I7-SUM(E12:K12))<I7/C5,I7-SUM(E12:K12),I7/C5),0) -> 0 | M12: =IF(SUM(E12:L12)<I7,IF((I7-SUM(E12:L12))<I7/C5,I7-SUM(E12:L12),I7/C5),0) -> 0 | N12: =IF(SUM(E12:M12)<I7,IF((I7-SUM(E12:M12))<I7/C5,I7-SUM(E12:M12),I7/C5),0) -> 0 | O12: =IF(SUM(E12:N12)<I7,IF((I7-SUM(E12:N12))<I7/C5,I7-SUM(E12:N12),I7/C5),0) -> 0 | P12: =IF(SUM(E12:O12)<I7,IF((I7-SUM(E12:O12))<I7/C5,I7-SUM(E12:O12),I7/C5),0) -> 0 | Q12: =IF(SUM(E12:P12)<I7,IF((I7-SUM(E12:P12))<I7/C5,I7-SUM(E12:P12),I7/C5),0) -> 0 | R12: =IF(SUM(E12:Q12)<I7,IF((I7-SUM(E12:Q12))<I7/C5,I7-SUM(E12:Q12),I7/C5),0) -> 0 | S12: =IF(SUM(E12:R12)<I7,IF((I7-SUM(E12:R12))<I7/C5,I7-SUM(E12:R12),I7/C5),0) -> 0 | T12: =IF(SUM(E12:S12)<I7,IF((I7-SUM(E12:S12))<I7/C5,I7-SUM(E12:S12),I7/C5),0) -> 0 | U12: =IF(SUM(E12:T12)<I7,IF((I7-SUM(E12:T12))<I7/C5,I7-SUM(E12:T12),I7/C5),0) -> 0 | V12: =IF(SUM(E12:U12)<I7,IF((I7-SUM(E12:U12))<I7/C5,I7-SUM(E12:U12),I7/C5),0) -> 0 | W12: =IF(SUM(E12:V12)<I7,IF((I7-SUM(E12:V12))<I7/C5,I7-SUM(E12:V12),I7/C5),0) -> 0 | X12: =IF(SUM(E12:W12)<I7,IF((I7-SUM(E12:W12))<I7/C5,I7-SUM(E12:W12),I7/C5),0) -> 0
B13: 第六年投资在各年的折旧 | D13: =SUM(E13:X13) -> 0 | J13: =K13*(1-J6/12) -> 0 | K13: =J7/C5 -> 0 | L13: =IF(SUM(E13:K13)<J7,IF((J7-SUM(E13:K13))<J7/C5,J7-SUM(E13:K13),J7/C5),0) -> 0 | M13: =IF(SUM(E13:L13)<J7,IF((J7-SUM(E13:L13))<J7/C5,J7-SUM(E13:L13),J7/C5),0) -> 0 | N13: =IF(SUM(E13:M13)<J7,IF((J7-SUM(E13:M13))<J7/C5,J7-SUM(E13:M13),J7/C5),0) -> 0 | O13: =IF(SUM(E13:N13)<J7,IF((J7-SUM(E13:N13))<J7/C5,J7-SUM(E13:N13),J7/C5),0) -> 0 | P13: =IF(SUM(E13:O13)<J7,IF((J7-SUM(E13:O13))<J7/C5,J7-SUM(E13:O13),J7/C5),0) -> 0 | Q13: =IF(SUM(E13:P13)<J7,IF((J7-SUM(E13:P13))<J7/C5,J7-SUM(E13:P13),J7/C5),0) -> 0 | R13: =IF(SUM(E13:Q13)<J7,IF((J7-SUM(E13:Q13))<J7/C5,J7-SUM(E13:Q13),J7/C5),0) -> 0 | S13: =IF(SUM(E13:R13)<J7,IF((J7-SUM(E13:R13))<J7/C5,J7-SUM(E13:R13),J7/C5),0) -> 0 | T13: =IF(SUM(E13:S13)<J7,IF((J7-SUM(E13:S13))<J7/C5,J7-SUM(E13:S13),J7/C5),0) -> 0 | U13: =IF(SUM(E13:T13)<J7,IF((J7-SUM(E13:T13))<J7/C5,J7-SUM(E13:T13),J7/C5),0) -> 0 | V13: =IF(SUM(E13:U13)<J7,IF((J7-SUM(E13:U13))<J7/C5,J7-SUM(E13:U13),J7/C5),0) -> 0 | W13: =IF(SUM(E13:V13)<J7,IF((J7-SUM(E13:V13))<J7/C5,J7-SUM(E13:V13),J7/C5),0) -> 0 | X13: =IF(SUM(E13:W13)<J7,IF((J7-SUM(E13:W13))<J7/C5,J7-SUM(E13:W13),J7/C5),0) -> 0
B14: 第七年投资在各年的折旧 | D14: =SUM(E14:X14) -> 0 | K14: =L14*(1-K6/12) -> 0 | L14: =K7/C5 -> 0 | M14: =IF(SUM(E14:L14)<K7,IF((K7-SUM(E14:L14))<K7/C5,K7-SUM(E14:L14),K7/C5),0) -> 0 | N14: =IF(SUM(E14:M14)<K7,IF((K7-SUM(E14:M14))<K7/C5,K7-SUM(E14:M14),K7/C5),0) -> 0 | O14: =IF(SUM(E14:N14)<K7,IF((K7-SUM(E14:N14))<K7/C5,K7-SUM(E14:N14),K7/C5),0) -> 0 | P14: =IF(SUM(E14:O14)<K7,IF((K7-SUM(E14:O14))<K7/C5,K7-SUM(E14:O14),K7/C5),0) -> 0 | Q14: =IF(SUM(E14:P14)<K7,IF((K7-SUM(E14:P14))<K7/C5,K7-SUM(E14:P14),K7/C5),0) -> 0 | R14: =IF(SUM(E14:Q14)<K7,IF((K7-SUM(E14:Q14))<K7/C5,K7-SUM(E14:Q14),K7/C5),0) -> 0 | S14: =IF(SUM(E14:R14)<K7,IF((K7-SUM(E14:R14))<K7/C5,K7-SUM(E14:R14),K7/C5),0) -> 0 | T14: =IF(SUM(E14:S14)<K7,IF((K7-SUM(E14:S14))<K7/C5,K7-SUM(E14:S14),K7/C5),0) -> 0 | U14: =IF(SUM(E14:T14)<K7,IF((K7-SUM(E14:T14))<K7/C5,K7-SUM(E14:T14),K7/C5),0) -> 0 | V14: =IF(SUM(E14:U14)<K7,IF((K7-SUM(E14:U14))<K7/C5,K7-SUM(E14:U14),K7/C5),0) -> 0 | W14: =IF(SUM(E14:V14)<K7,IF((K7-SUM(E14:V14))<K7/C5,K7-SUM(E14:V14),K7/C5),0) -> 0 | X14: =IF(SUM(E14:W14)<K7,IF((K7-SUM(E14:W14))<K7/C5,K7-SUM(E14:W14),K7/C5),0) -> 0
B15: 第八年投资在各年的折旧 | D15: =SUM(E15:X15) -> 0 | L15: =M15*(1-L6/12) -> 0 | M15: =L7/C5 -> 0 | N15: =IF(SUM(E15:M15)<L7,IF((L7-SUM(E15:M15))<L7/C5,L7-SUM(E15:M15),L7/C5),0) -> 0 | O15: =IF(SUM(E15:N15)<L7,IF((L7-SUM(E15:N15))<L7/C5,L7-SUM(E15:N15),L7/C5),0) -> 0 | P15: =IF(SUM(E15:O15)<L7,IF((L7-SUM(E15:O15))<L7/C5,L7-SUM(E15:O15),L7/C5),0) -> 0 | Q15: =IF(SUM(E15:P15)<L7,IF((L7-SUM(E15:P15))<L7/C5,L7-SUM(E15:P15),L7/C5),0) -> 0 | R15: =IF(SUM(E15:Q15)<L7,IF((L7-SUM(E15:Q15))<L7/C5,L7-SUM(E15:Q15),L7/C5),0) -> 0 | S15: =IF(SUM(E15:R15)<L7,IF((L7-SUM(E15:R15))<L7/C5,L7-SUM(E15:R15),L7/C5),0) -> 0 | T15: =IF(SUM(E15:S15)<L7,IF((L7-SUM(E15:S15))<L7/C5,L7-SUM(E15:S15),L7/C5),0) -> 0 | U15: =IF(SUM(E15:T15)<L7,IF((L7-SUM(E15:T15))<L7/C5,L7-SUM(E15:T15),L7/C5),0) -> 0 | V15: =IF(SUM(E15:U15)<L7,IF((L7-SUM(E15:U15))<L7/C5,L7-SUM(E15:U15),L7/C5),0) -> 0 | W15: =IF(SUM(E15:V15)<L7,IF((L7-SUM(E15:V15))<L7/C5,L7-SUM(E15:V15),L7/C5),0) -> 0 | X15: =IF(SUM(E15:W15)<L7,IF((L7-SUM(E15:W15))<L7/C5,L7-SUM(E15:W15),L7/C5),0) -> 0
B16: 第九年投资在各年的折旧 | D16: =SUM(E16:X16) -> 0 | M16: =N16*(1-M6/12) -> 0 | N16: =M7/C5 -> 0 | O16: =IF(SUM(E16:N16)<M7,IF((M7-SUM(E16:N16))<M7/C5,M7-SUM(E16:N16),M7/C5),0) -> 0 | P16: =IF(SUM(E16:O16)<M7,IF((M7-SUM(E16:O16))<M7/C5,M7-SUM(E16:O16),M7/C5),0) -> 0 | Q16: =IF(SUM(E16:P16)<M7,IF((M7-SUM(E16:P16))<M7/C5,M7-SUM(E16:P16),M7/C5),0) -> 0 | R16: =IF(SUM(E16:Q16)<M7,IF((M7-SUM(E16:Q16))<M7/C5,M7-SUM(E16:Q16),M7/C5),0) -> 0 | S16: =IF(SUM(E16:R16)<M7,IF((M7-SUM(E16:R16))<M7/C5,M7-SUM(E16:R16),M7/C5),0) -> 0 | T16: =IF(SUM(E16:S16)<M7,IF((M7-SUM(E16:S16))<M7/C5,M7-SUM(E16:S16),M7/C5),0) -> 0 | U16: =IF(SUM(E16:T16)<M7,IF((M7-SUM(E16:T16))<M7/C5,M7-SUM(E16:T16),M7/C5),0) -> 0 | V16: =IF(SUM(E16:U16)<M7,IF((M7-SUM(E16:U16))<M7/C5,M7-SUM(E16:U16),M7/C5),0) -> 0 | W16: =IF(SUM(E16:V16)<M7,IF((M7-SUM(E16:V16))<M7/C5,M7-SUM(E16:V16),M7/C5),0) -> 0 | X16: =IF(SUM(E16:W16)<M7,IF((M7-SUM(E16:W16))<M7/C5,M7-SUM(E16:W16),M7/C5),0) -> 0
B17: 第十年投资在各年的折旧 | D17: =SUM(E17:X17) -> 0 | N17: =O17*(1-N6/12) -> 0 | O17: =N7/C5 -> 0 | P17: =IF(SUM(E17:O17)<N7,IF((N7-SUM(E17:O17))<N7/C5,N7-SUM(E17:O17),N7/C5),0) -> 0 | Q17: =IF(SUM(E17:P17)<N7,IF((N7-SUM(E17:P17))<N7/C5,N7-SUM(E17:P17),N7/C5),0) -> 0 | R17: =IF(SUM(E17:Q17)<N7,IF((N7-SUM(E17:Q17))<N7/C5,N7-SUM(E17:Q17),N7/C5),0) -> 0 | S17: =IF(SUM(E17:R17)<N7,IF((N7-SUM(E17:R17))<N7/C5,N7-SUM(E17:R17),N7/C5),0) -> 0 | T17: =IF(SUM(E17:S17)<N7,IF((N7-SUM(E17:S17))<N7/C5,N7-SUM(E17:S17),N7/C5),0) -> 0 | U17: =IF(SUM(E17:T17)<N7,IF((N7-SUM(E17:T17))<N7/C5,N7-SUM(E17:T17),N7/C5),0) -> 0 | V17: =IF(SUM(E17:U17)<N7,IF((N7-SUM(E17:U17))<N7/C5,N7-SUM(E17:U17),N7/C5),0) -> 0 | W17: =IF(SUM(E17:V17)<N7,IF((N7-SUM(E17:V17))<N7/C5,N7-SUM(E17:V17),N7/C5),0) -> 0 | X17: =IF(SUM(E17:W17)<N7,IF((N7-SUM(E17:W17))<N7/C5,N7-SUM(E17:W17),N7/C5),0) -> 0
B18: 第十一年投资在各年的折旧 | D18: =SUM(E18:X18) -> 0 | O18: =P18*(1-O6/12) -> 0 | P18: =O7/C5 -> 0 | Q18: =IF(SUM(E18:P18)<O7,IF((O7-SUM(E18:P18))<O7/C5,O7-SUM(E18:P18),O7/C5),0) -> 0 | R18: =IF(SUM(E18:Q18)<O7,IF((O7-SUM(E18:Q18))<O7/C5,O7-SUM(E18:Q18),O7/C5),0) -> 0 | S18: =IF(SUM(E18:R18)<O7,IF((O7-SUM(E18:R18))<O7/C5,O7-SUM(E18:R18),O7/C5),0) -> 0 | T18: =IF(SUM(E18:S18)<O7,IF((O7-SUM(E18:S18))<O7/C5,O7-SUM(E18:S18),O7/C5),0) -> 0 | U18: =IF(SUM(E18:T18)<O7,IF((O7-SUM(E18:T18))<O7/C5,O7-SUM(E18:T18),O7/C5),0) -> 0 | V18: =IF(SUM(E18:U18)<O7,IF((O7-SUM(E18:U18))<O7/C5,O7-SUM(E18:U18),O7/C5),0) -> 0 | W18: =IF(SUM(E18:V18)<O7,IF((O7-SUM(E18:V18))<O7/C5,O7-SUM(E18:V18),O7/C5),0) -> 0 | X18: =IF(SUM(E18:W18)<O7,IF((O7-SUM(E18:W18))<O7/C5,O7-SUM(E18:W18),O7/C5),0) -> 0
B20: 传输网设备类投资累计折旧 | D20: =SUM(E20:X20) -> 0 | E20: =SUM(E24:E34) -> 0 | F20: =SUM(F24:F34) -> 0 | G20: =SUM(G24:G34) -> 0 | H20: =SUM(H24:H34) -> 0 | I20: =SUM(I24:I34) -> 0 | J20: =SUM(J24:J34) -> 0 | K20: =SUM(K24:K34) -> 0 | L20: =SUM(L24:L34) -> 0 | ... X20: =SUM(X24:X34) -> 0
B21: 折旧年限 | C21: 7
B22: 当年投产月份 | E22: 0 | F22: 0 | G22: 0 | H22: 6 | I22: 0 | J22: 0 | K22: 0 | L22: 0 | M22: 0 | N22: 0 | O22: 0
B23: 各年传输网设备类投资规模 | D23: =SUM(E23:O23) -> 0
B24: 第一年投资在各年的折旧 | D24: =SUM(E24:X24) -> 0 | E24: =F24*(1-E22/12) -> 0 | F24: =E23/C21 -> 0 | G24: =IF(SUM(E24:F24)<E23,IF((E23-SUM(E24:F24))<E23/C21,E23-SUM(E24:F24),E23/C21),0) -> 0 | H24: =IF(SUM(E24:G24)<E23,IF((E23-SUM(E24:G24))<E23/C21,E23-SUM(E24:G24),E23/C21),0) -> 0 | I24: =IF(SUM(E24:H24)<E23,IF((E23-SUM(E24:H24))<E23/C21,E23-SUM(E24:H24),E23/C21),0) -> 0 | J24: =IF(SUM(E24:I24)<E23,IF((E23-SUM(E24:I24))<E23/C21,E23-SUM(E24:I24),E23/C21),0) -> 0 | K24: =IF(SUM(E24:J24)<E23,IF((E23-SUM(E24:J24))<E23/C21,E23-SUM(E24:J24),E23/C21),0) -> 0 | L24: =IF(SUM(E24:K24)<E23,IF((E23-SUM(E24:K24))<E23/C21,E23-SUM(E24:K24),E23/C21),0) -> 0 | M24: =IF(SUM(E24:L24)<E23,IF((E23-SUM(E24:L24))<E23/C21,E23-SUM(E24:L24),E23/C21),0) -> 0 | N24: =IF(SUM(E24:M24)<E23,IF((E23-SUM(E24:M24))<E23/C21,E23-SUM(E24:M24),E23/C21),0) -> 0 | O24: =IF(SUM(E24:N24)<E23,IF((E23-SUM(E24:N24))<E23/C21,E23-SUM(E24:N24),E23/C21),0) -> 0 | P24: =IF(SUM(E24:O24)<E23,IF((E23-SUM(E24:O24))<E23/C21,E23-SUM(E24:O24),E23/C21),0) -> 0 | Q24: =IF(SUM(E24:P24)<E23,IF((E23-SUM(E24:P24))<E23/C21,E23-SUM(E24:P24),E23/C21),0) -> 0 | R24: =IF(SUM(E24:Q24)<E23,IF((E23-SUM(E24:Q24))<E23/C21,E23-SUM(E24:Q24),E23/C21),0) -> 0 | S24: =IF(SUM(E24:R24)<E23,IF((E23-SUM(E24:R24))<E23/C21,E23-SUM(E24:R24),E23/C21),0) -> 0 | T24: =IF(SUM(E24:S24)<E23,IF((E23-SUM(E24:S24))<E23/C21,E23-SUM(E24:S24),E23/C21),0) -> 0 | U24: =IF(SUM(E24:T24)<E23,IF((E23-SUM(E24:T24))<E23/C21,E23-SUM(E24:T24),E23/C21),0) -> 0 | V24: =IF(SUM(E24:U24)<E23,IF((E23-SUM(E24:U24))<E23/C21,E23-SUM(E24:U24),E23/C21),0) -> 0 | W24: =IF(SUM(E24:V24)<E23,IF((E23-SUM(E24:V24))<E23/C21,E23-SUM(E24:V24),E23/C21),0) -> 0 | X24: =IF(SUM(E24:W24)<E23,IF((E23-SUM(E24:W24))<E23/C21,E23-SUM(E24:W24),E23/C21),0) -> 0
B25: 第二年投资在各年的折旧 | D25: =SUM(E25:X25) -> 0 | F25: =G25*(1-F22/12) -> 0 | G25: =F23/C21 -> 0 | H25: =IF(SUM(E25:G25)<F23,IF((F23-SUM(E25:G25))<F23/C21,F23-SUM(E25:G25),F23/C21),0) -> 0 | I25: =IF(SUM(E25:H25)<F23,IF((F23-SUM(E25:H25))<F23/C21,F23-SUM(E25:H25),F23/C21),0) -> 0 | J25: =IF(SUM(E25:I25)<F23,IF((F23-SUM(E25:I25))<F23/C21,F23-SUM(E25:I25),F23/C21),0) -> 0 | K25: =IF(SUM(E25:J25)<F23,IF((F23-SUM(E25:J25))<F23/C21,F23-SUM(E25:J25),F23/C21),0) -> 0 | L25: =IF(SUM(E25:K25)<F23,IF((F23-SUM(E25:K25))<F23/C21,F23-SUM(E25:K25),F23/C21),0) -> 0 | M25: =IF(SUM(E25:L25)<F23,IF((F23-SUM(E25:L25))<F23/C21,F23-SUM(E25:L25),F23/C21),0) -> 0 | N25: =IF(SUM(E25:M25)<F23,IF((F23-SUM(E25:M25))<F23/C21,F23-SUM(E25:M25),F23/C21),0) -> 0 | O25: =IF(SUM(E25:N25)<F23,IF((F23-SUM(E25:N25))<F23/C21,F23-SUM(E25:N25),F23/C21),0) -> 0 | P25: =IF(SUM(E25:O25)<F23,IF((F23-SUM(E25:O25))<F23/C21,F23-SUM(E25:O25),F23/C21),0) -> 0 | Q25: =IF(SUM(E25:P25)<F23,IF((F23-SUM(E25:P25))<F23/C21,F23-SUM(E25:P25),F23/C21),0) -> 0 | R25: =IF(SUM(E25:Q25)<F23,IF((F23-SUM(E25:Q25))<F23/C21,F23-SUM(E25:Q25),F23/C21),0) -> 0 | S25: =IF(SUM(E25:R25)<F23,IF((F23-SUM(E25:R25))<F23/C21,F23-SUM(E25:R25),F23/C21),0) -> 0 | T25: =IF(SUM(E25:S25)<F23,IF((F23-SUM(E25:S25))<F23/C21,F23-SUM(E25:S25),F23/C21),0) -> 0 | U25: =IF(SUM(E25:T25)<F23,IF((F23-SUM(E25:T25))<F23/C21,F23-SUM(E25:T25),F23/C21),0) -> 0 | V25: =IF(SUM(E25:U25)<F23,IF((F23-SUM(E25:U25))<F23/C21,F23-SUM(E25:U25),F23/C21),0) -> 0 | W25: =IF(SUM(E25:V25)<F23,IF((F23-SUM(E25:V25))<F23/C21,F23-SUM(E25:V25),F23/C21),0) -> 0 | X25: =IF(SUM(E25:W25)<F23,IF((F23-SUM(E25:W25))<F23/C21,F23-SUM(E25:W25),F23/C21),0) -> 0
B26: 第三年投资在各年的折旧 | D26: =SUM(E26:X26) -> 0 | G26: =H26*(1-G22/12) -> 0 | H26: =G23/C21 -> 0 | I26: =IF(SUM(E26:H26)<G23,IF((G23-SUM(E26:H26))<G23/C21,G23-SUM(E26:H26),G23/C21),0) -> 0 | J26: =IF(SUM(E26:I26)<G23,IF((G23-SUM(E26:I26))<G23/C21,G23-SUM(E26:I26),G23/C21),0) -> 0 | K26: =IF(SUM(E26:J26)<G23,IF((G23-SUM(E26:J26))<G23/C21,G23-SUM(E26:J26),G23/C21),0) -> 0 | L26: =IF(SUM(E26:K26)<G23,IF((G23-SUM(E26:K26))<G23/C21,G23-SUM(E26:K26),G23/C21),0) -> 0 | M26: =IF(SUM(E26:L26)<G23,IF((G23-SUM(E26:L26))<G23/C21,G23-SUM(E26:L26),G23/C21),0) -> 0 | N26: =IF(SUM(E26:M26)<G23,IF((G23-SUM(E26:M26))<G23/C21,G23-SUM(E26:M26),G23/C21),0) -> 0 | O26: =IF(SUM(E26:N26)<G23,IF((G23-SUM(E26:N26))<G23/C21,G23-SUM(E26:N26),G23/C21),0) -> 0 | P26: =IF(SUM(E26:O26)<G23,IF((G23-SUM(E26:O26))<G23/C21,G23-SUM(E26:O26),G23/C21),0) -> 0 | Q26: =IF(SUM(E26:P26)<G23,IF((G23-SUM(E26:P26))<G23/C21,G23-SUM(E26:P26),G23/C21),0) -> 0 | R26: =IF(SUM(E26:Q26)<G23,IF((G23-SUM(E26:Q26))<G23/C21,G23-SUM(E26:Q26),G23/C21),0) -> 0 | S26: =IF(SUM(E26:R26)<G23,IF((G23-SUM(E26:R26))<G23/C21,G23-SUM(E26:R26),G23/C21),0) -> 0 | T26: =IF(SUM(E26:S26)<G23,IF((G23-SUM(E26:S26))<G23/C21,G23-SUM(E26:S26),G23/C21),0) -> 0 | U26: =IF(SUM(E26:T26)<G23,IF((G23-SUM(E26:T26))<G23/C21,G23-SUM(E26:T26),G23/C21),0) -> 0 | V26: =IF(SUM(E26:U26)<G23,IF((G23-SUM(E26:U26))<G23/C21,G23-SUM(E26:U26),G23/C21),0) -> 0 | W26: =IF(SUM(E26:V26)<G23,IF((G23-SUM(E26:V26))<G23/C21,G23-SUM(E26:V26),G23/C21),0) -> 0 | X26: =IF(SUM(E26:W26)<G23,IF((G23-SUM(E26:W26))<G23/C21,G23-SUM(E26:W26),G23/C21),0) -> 0
B27: 第四年投资在各年的折旧 | D27: =SUM(E27:X27) -> 0 | H27: =I27*(1-H22/12) -> 0 | I27: =H23/C21 -> 0 | J27: =IF(SUM(E27:I27)<H23,IF((H23-SUM(E27:I27))<H23/C21,H23-SUM(E27:I27),H23/C21),0) -> 0 | K27: =IF(SUM(E27:J27)<H23,IF((H23-SUM(E27:J27))<H23/C21,H23-SUM(E27:J27),H23/C21),0) -> 0 | L27: =IF(SUM(E27:K27)<H23,IF((H23-SUM(E27:K27))<H23/C21,H23-SUM(E27:K27),H23/C21),0) -> 0 | M27: =IF(SUM(E27:L27)<H23,IF((H23-SUM(E27:L27))<H23/C21,H23-SUM(E27:L27),H23/C21),0) -> 0 | N27: =IF(SUM(E27:M27)<H23,IF((H23-SUM(E27:M27))<H23/C21,H23-SUM(E27:M27),H23/C21),0) -> 0 | O27: =IF(SUM(E27:N27)<H23,IF((H23-SUM(E27:N27))<H23/C21,H23-SUM(E27:N27),H23/C21),0) -> 0 | P27: =IF(SUM(E27:O27)<H23,IF((H23-SUM(E27:O27))<H23/C21,H23-SUM(E27:O27),H23/C21),0) -> 0 | Q27: =IF(SUM(E27:P27)<H23,IF((H23-SUM(E27:P27))<H23/C21,H23-SUM(E27:P27),H23/C21),0) -> 0 | R27: =IF(SUM(E27:Q27)<H23,IF((H23-SUM(E27:Q27))<H23/C21,H23-SUM(E27:Q27),H23/C21),0) -> 0 | S27: =IF(SUM(E27:R27)<H23,IF((H23-SUM(E27:R27))<H23/C21,H23-SUM(E27:R27),H23/C21),0) -> 0 | T27: =IF(SUM(E27:S27)<H23,IF((H23-SUM(E27:S27))<H23/C21,H23-SUM(E27:S27),H23/C21),0) -> 0 | U27: =IF(SUM(E27:T27)<H23,IF((H23-SUM(E27:T27))<H23/C21,H23-SUM(E27:T27),H23/C21),0) -> 0 | V27: =IF(SUM(E27:U27)<H23,IF((H23-SUM(E27:U27))<H23/C21,H23-SUM(E27:U27),H23/C21),0) -> 0 | W27: =IF(SUM(E27:V27)<H23,IF((H23-SUM(E27:V27))<H23/C21,H23-SUM(E27:V27),H23/C21),0) -> 0 | X27: =IF(SUM(E27:W27)<H23,IF((H23-SUM(E27:W27))<H23/C21,H23-SUM(E27:W27),H23/C21),0) -> 0
B28: 第五年投资在各年的折旧 | D28: =SUM(E28:X28) -> 0 | I28: =J28*(1-I22/12) -> 0 | J28: =I23/C21 -> 0 | K28: =IF(SUM(E28:J28)<I23,IF((I23-SUM(E28:J28))<I23/C21,I23-SUM(E28:J28),I23/C21),0) -> 0 | L28: =IF(SUM(E28:K28)<I23,IF((I23-SUM(E28:K28))<I23/C21,I23-SUM(E28:K28),I23/C21),0) -> 0 | M28: =IF(SUM(E28:L28)<I23,IF((I23-SUM(E28:L28))<I23/C21,I23-SUM(E28:L28),I23/C21),0) -> 0 | N28: =IF(SUM(E28:M28)<I23,IF((I23-SUM(E28:M28))<I23/C21,I23-SUM(E28:M28),I23/C21),0) -> 0 | O28: =IF(SUM(E28:N28)<I23,IF((I23-SUM(E28:N28))<I23/C21,I23-SUM(E28:N28),I23/C21),0) -> 0 | P28: =IF(SUM(E28:O28)<I23,IF((I23-SUM(E28:O28))<I23/C21,I23-SUM(E28:O28),I23/C21),0) -> 0 | Q28: =IF(SUM(E28:P28)<I23,IF((I23-SUM(E28:P28))<I23/C21,I23-SUM(E28:P28),I23/C21),0) -> 0 | R28: =IF(SUM(E28:Q28)<I23,IF((I23-SUM(E28:Q28))<I23/C21,I23-SUM(E28:Q28),I23/C21),0) -> 0 | S28: =IF(SUM(E28:R28)<I23,IF((I23-SUM(E28:R28))<I23/C21,I23-SUM(E28:R28),I23/C21),0) -> 0 | T28: =IF(SUM(E28:S28)<I23,IF((I23-SUM(E28:S28))<I23/C21,I23-SUM(E28:S28),I23/C21),0) -> 0 | U28: =IF(SUM(E28:T28)<I23,IF((I23-SUM(E28:T28))<I23/C21,I23-SUM(E28:T28),I23/C21),0) -> 0 | V28: =IF(SUM(E28:U28)<I23,IF((I23-SUM(E28:U28))<I23/C21,I23-SUM(E28:U28),I23/C21),0) -> 0 | W28: =IF(SUM(E28:V28)<I23,IF((I23-SUM(E28:V28))<I23/C21,I23-SUM(E28:V28),I23/C21),0) -> 0 | X28: =IF(SUM(E28:W28)<I23,IF((I23-SUM(E28:W28))<I23/C21,I23-SUM(E28:W28),I23/C21),0) -> 0
B29: 第六年投资在各年的折旧 | D29: =SUM(E29:X29) -> 0 | J29: =K29*(1-J22/12) -> 0 | K29: =J23/C21 -> 0 | L29: =IF(SUM(E29:K29)<J23,IF((J23-SUM(E29:K29))<J23/C21,J23-SUM(E29:K29),J23/C21),0) -> 0 | M29: =IF(SUM(E29:L29)<J23,IF((J23-SUM(E29:L29))<J23/C21,J23-SUM(E29:L29),J23/C21),0) -> 0 | N29: =IF(SUM(E29:M29)<J23,IF((J23-SUM(E29:M29))<J23/C21,J23-SUM(E29:M29),J23/C21),0) -> 0 | O29: =IF(SUM(E29:N29)<J23,IF((J23-SUM(E29:N29))<J23/C21,J23-SUM(E29:N29),J23/C21),0) -> 0 | P29: =IF(SUM(E29:O29)<J23,IF((J23-SUM(E29:O29))<J23/C21,J23-SUM(E29:O29),J23/C21),0) -> 0 | Q29: =IF(SUM(E29:P29)<J23,IF((J23-SUM(E29:P29))<J23/C21,J23-SUM(E29:P29),J23/C21),0) -> 0 | R29: =IF(SUM(E29:Q29)<J23,IF((J23-SUM(E29:Q29))<J23/C21,J23-SUM(E29:Q29),J23/C21),0) -> 0 | S29: =IF(SUM(E29:R29)<J23,IF((J23-SUM(E29:R29))<J23/C21,J23-SUM(E29:R29),J23/C21),0) -> 0 | T29: =IF(SUM(E29:S29)<J23,IF((J23-SUM(E29:S29))<J23/C21,J23-SUM(E29:S29),J23/C21),0) -> 0 | U29: =IF(SUM(E29:T29)<J23,IF((J23-SUM(E29:T29))<J23/C21,J23-SUM(E29:T29),J23/C21),0) -> 0 | V29: =IF(SUM(E29:U29)<J23,IF((J23-SUM(E29:U29))<J23/C21,J23-SUM(E29:U29),J23/C21),0) -> 0 | W29: =IF(SUM(E29:V29)<J23,IF((J23-SUM(E29:V29))<J23/C21,J23-SUM(E29:V29),J23/C21),0) -> 0 | X29: =IF(SUM(E29:W29)<J23,IF((J23-SUM(E29:W29))<J23/C21,J23-SUM(E29:W29),J23/C21),0) -> 0
B30: 第七年投资在各年的折旧 | D30: =SUM(E30:X30) -> 0 | K30: =L30*(1-K22/12) -> 0 | L30: =K23/C21 -> 0 | M30: =IF(SUM(E30:L30)<K23,IF((K23-SUM(E30:L30))<K23/C21,K23-SUM(E30:L30),K23/C21),0) -> 0 | N30: =IF(SUM(E30:M30)<K23,IF((K23-SUM(E30:M30))<K23/C21,K23-SUM(E30:M30),K23/C21),0) -> 0 | O30: =IF(SUM(E30:N30)<K23,IF((K23-SUM(E30:N30))<K23/C21,K23-SUM(E30:N30),K23/C21),0) -> 0 | P30: =IF(SUM(E30:O30)<K23,IF((K23-SUM(E30:O30))<K23/C21,K23-SUM(E30:O30),K23/C21),0) -> 0 | Q30: =IF(SUM(E30:P30)<K23,IF((K23-SUM(E30:P30))<K23/C21,K23-SUM(E30:P30),K23/C21),0) -> 0 | R30: =IF(SUM(E30:Q30)<K23,IF((K23-SUM(E30:Q30))<K23/C21,K23-SUM(E30:Q30),K23/C21),0) -> 0 | S30: =IF(SUM(E30:R30)<K23,IF((K23-SUM(E30:R30))<K23/C21,K23-SUM(E30:R30),K23/C21),0) -> 0 | T30: =IF(SUM(E30:S30)<K23,IF((K23-SUM(E30:S30))<K23/C21,K23-SUM(E30:S30),K23/C21),0) -> 0 | U30: =IF(SUM(E30:T30)<K23,IF((K23-SUM(E30:T30))<K23/C21,K23-SUM(E30:T30),K23/C21),0) -> 0 | V30: =IF(SUM(E30:U30)<K23,IF((K23-SUM(E30:U30))<K23/C21,K23-SUM(E30:U30),K23/C21),0) -> 0 | W30: =IF(SUM(E30:V30)<K23,IF((K23-SUM(E30:V30))<K23/C21,K23-SUM(E30:V30),K23/C21),0) -> 0 | X30: =IF(SUM(E30:W30)<K23,IF((K23-SUM(E30:W30))<K23/C21,K23-SUM(E30:W30),K23/C21),0) -> 0
B31: 第八年投资在各年的折旧 | D31: =SUM(E31:X31) -> 0 | L31: =M31*(1-L22/12) -> 0 | M31: =L23/C21 -> 0 | N31: =IF(SUM(E31:M31)<L23,IF((L23-SUM(E31:M31))<L23/C21,L23-SUM(E31:M31),L23/C21),0) -> 0 | O31: =IF(SUM(E31:N31)<L23,IF((L23-SUM(E31:N31))<L23/C21,L23-SUM(E31:N31),L23/C21),0) -> 0 | P31: =IF(SUM(E31:O31)<L23,IF((L23-SUM(E31:O31))<L23/C21,L23-SUM(E31:O31),L23/C21),0) -> 0 | Q31: =IF(SUM(E31:P31)<L23,IF((L23-SUM(E31:P31))<L23/C21,L23-SUM(E31:P31),L23/C21),0) -> 0 | R31: =IF(SUM(E31:Q31)<L23,IF((L23-SUM(E31:Q31))<L23/C21,L23-SUM(E31:Q31),L23/C21),0) -> 0 | S31: =IF(SUM(E31:R31)<L23,IF((L23-SUM(E31:R31))<L23/C21,L23-SUM(E31:R31),L23/C21),0) -> 0 | T31: =IF(SUM(E31:S31)<L23,IF((L23-SUM(E31:S31))<L23/C21,L23-SUM(E31:S31),L23/C21),0) -> 0 | U31: =IF(SUM(E31:T31)<L23,IF((L23-SUM(E31:T31))<L23/C21,L23-SUM(E31:T31),L23/C21),0) -> 0 | V31: =IF(SUM(E31:U31)<L23,IF((L23-SUM(E31:U31))<L23/C21,L23-SUM(E31:U31),L23/C21),0) -> 0 | W31: =IF(SUM(E31:V31)<L23,IF((L23-SUM(E31:V31))<L23/C21,L23-SUM(E31:V31),L23/C21),0) -> 0 | X31: =IF(SUM(E31:W31)<L23,IF((L23-SUM(E31:W31))<L23/C21,L23-SUM(E31:W31),L23/C21),0) -> 0
B32: 第九年投资在各年的折旧 | D32: =SUM(E32:X32) -> 0 | M32: =N32*(1-M22/12) -> 0 | N32: =M23/C21 -> 0 | O32: =IF(SUM(E32:N32)<M23,IF((M23-SUM(E32:N32))<M23/C21,M23-SUM(E32:N32),M23/C21),0) -> 0 | P32: =IF(SUM(E32:O32)<M23,IF((M23-SUM(E32:O32))<M23/C21,M23-SUM(E32:O32),M23/C21),0) -> 0 | Q32: =IF(SUM(E32:P32)<M23,IF((M23-SUM(E32:P32))<M23/C21,M23-SUM(E32:P32),M23/C21),0) -> 0 | R32: =IF(SUM(E32:Q32)<M23,IF((M23-SUM(E32:Q32))<M23/C21,M23-SUM(E32:Q32),M23/C21),0) -> 0 | S32: =IF(SUM(E32:R32)<M23,IF((M23-SUM(E32:R32))<M23/C21,M23-SUM(E32:R32),M23/C21),0) -> 0 | T32: =IF(SUM(E32:S32)<M23,IF((M23-SUM(E32:S32))<M23/C21,M23-SUM(E32:S32),M23/C21),0) -> 0 | U32: =IF(SUM(E32:T32)<M23,IF((M23-SUM(E32:T32))<M23/C21,M23-SUM(E32:T32),M23/C21),0) -> 0 | V32: =IF(SUM(E32:U32)<M23,IF((M23-SUM(E32:U32))<M23/C21,M23-SUM(E32:U32),M23/C21),0) -> 0 | W32: =IF(SUM(E32:V32)<M23,IF((M23-SUM(E32:V32))<M23/C21,M23-SUM(E32:V32),M23/C21),0) -> 0 | X32: =IF(SUM(E32:W32)<M23,IF((M23-SUM(E32:W32))<M23/C21,M23-SUM(E32:W32),M23/C21),0) -> 0
B33: 第十年投资在各年的折旧 | D33: =SUM(E33:X33) -> 0 | N33: =O33*(1-N22/12) -> 0 | O33: =N23/C21 -> 0 | P33: =IF(SUM(E33:O33)<N23,IF((N23-SUM(E33:O33))<N23/C21,N23-SUM(E33:O33),N23/C21),0) -> 0 | Q33: =IF(SUM(E33:P33)<N23,IF((N23-SUM(E33:P33))<N23/C21,N23-SUM(E33:P33),N23/C21),0) -> 0 | R33: =IF(SUM(E33:Q33)<N23,IF((N23-SUM(E33:Q33))<N23/C21,N23-SUM(E33:Q33),N23/C21),0) -> 0 | S33: =IF(SUM(E33:R33)<N23,IF((N23-SUM(E33:R33))<N23/C21,N23-SUM(E33:R33),N23/C21),0) -> 0 | T33: =IF(SUM(E33:S33)<N23,IF((N23-SUM(E33:S33))<N23/C21,N23-SUM(E33:S33),N23/C21),0) -> 0 | U33: =IF(SUM(E33:T33)<N23,IF((N23-SUM(E33:T33))<N23/C21,N23-SUM(E33:T33),N23/C21),0) -> 0 | V33: =IF(SUM(E33:U33)<N23,IF((N23-SUM(E33:U33))<N23/C21,N23-SUM(E33:U33),N23/C21),0) -> 0 | W33: =IF(SUM(E33:V33)<N23,IF((N23-SUM(E33:V33))<N23/C21,N23-SUM(E33:V33),N23/C21),0) -> 0 | X33: =IF(SUM(E33:W33)<N23,IF((N23-SUM(E33:W33))<N23/C21,N23-SUM(E33:W33),N23/C21),0) -> 0
B34: 第十一年投资在各年的折旧 | D34: =SUM(E34:X34) -> 0 | O34: =P34*(1-O22/12) -> 0 | P34: =O23/C21 -> 0 | Q34: =IF(SUM(E34:P34)<O23,IF((O23-SUM(E34:P34))<O23/C21,O23-SUM(E34:P34),O23/C21),0) -> 0 | R34: =IF(SUM(E34:Q34)<O23,IF((O23-SUM(E34:Q34))<O23/C21,O23-SUM(E34:Q34),O23/C21),0) -> 0 | S34: =IF(SUM(E34:R34)<O23,IF((O23-SUM(E34:R34))<O23/C21,O23-SUM(E34:R34),O23/C21),0) -> 0 | T34: =IF(SUM(E34:S34)<O23,IF((O23-SUM(E34:S34))<O23/C21,O23-SUM(E34:S34),O23/C21),0) -> 0 | U34: =IF(SUM(E34:T34)<O23,IF((O23-SUM(E34:T34))<O23/C21,O23-SUM(E34:T34),O23/C21),0) -> 0 | V34: =IF(SUM(E34:U34)<O23,IF((O23-SUM(E34:U34))<O23/C21,O23-SUM(E34:U34),O23/C21),0) -> 0 | W34: =IF(SUM(E34:V34)<O23,IF((O23-SUM(E34:V34))<O23/C21,O23-SUM(E34:V34),O23/C21),0) -> 0 | X34: =IF(SUM(E34:W34)<O23,IF((O23-SUM(E34:W34))<O23/C21,O23-SUM(E34:W34),O23/C21),0) -> 0
B36: 光缆及管道类投资累计折旧 | D36: =SUM(E36:X36) -> 0 | E36: =SUM(E40:E50) -> 0 | F36: =SUM(F40:F50) -> 0 | G36: =SUM(G40:G50) -> 0 | H36: =SUM(H40:H50) -> 0 | I36: =SUM(I40:I50) -> 0 | J36: =SUM(J40:J50) -> 0 | K36: =SUM(K40:K50) -> 0 | L36: =SUM(L40:L50) -> 0 | ... X36: =SUM(X40:X50) -> 0
B37: 折旧年限 | C37: 10
B38: 当年投产月份 | E38: 0 | F38: 0 | G38: 0 | H38: 0 | I38: 0 | J38: 0 | K38: 0 | L38: 0 | M38: 0 | N38: 0 | O38: 0
B39: 各年光缆及管道类投资规模 | D39: =SUM(E39:O39) -> 0
B40: 第一年投资在各年的折旧 | D40: =SUM(E40:X40) -> 0 | E40: =F40*(1-E38/12) -> 0 | F40: =E39/C37 -> 0 | G40: =IF(SUM(E40:F40)<E39,IF((E39-SUM(E40:F40))<E39/C37,E39-SUM(E40:F40),E39/C37),0) -> 0 | H40: =IF(SUM(E40:G40)<E39,IF((E39-SUM(E40:G40))<E39/C37,E39-SUM(E40:G40),E39/C37),0) -> 0 | I40: =IF(SUM(E40:H40)<E39,IF((E39-SUM(E40:H40))<E39/C37,E39-SUM(E40:H40),E39/C37),0) -> 0 | J40: =IF(SUM(E40:I40)<E39,IF((E39-SUM(E40:I40))<E39/C37,E39-SUM(E40:I40),E39/C37),0) -> 0 | K40: =IF(SUM(E40:J40)<E39,IF((E39-SUM(E40:J40))<E39/C37,E39-SUM(E40:J40),E39/C37),0) -> 0 | L40: =IF(SUM(E40:K40)<E39,IF((E39-SUM(E40:K40))<E39/C37,E39-SUM(E40:K40),E39/C37),0) -> 0 | M40: =IF(SUM(E40:L40)<E39,IF((E39-SUM(E40:L40))<E39/C37,E39-SUM(E40:L40),E39/C37),0) -> 0 | N40: =IF(SUM(E40:M40)<E39,IF((E39-SUM(E40:M40))<E39/C37,E39-SUM(E40:M40),E39/C37),0) -> 0 | O40: =IF(SUM(E40:N40)<E39,IF((E39-SUM(E40:N40))<E39/C37,E39-SUM(E40:N40),E39/C37),0) -> 0 | P40: =IF(SUM(E40:O40)<E39,IF((E39-SUM(E40:O40))<E39/C37,E39-SUM(E40:O40),E39/C37),0) -> 0 | Q40: =IF(SUM(E40:P40)<E39,IF((E39-SUM(E40:P40))<E39/C37,E39-SUM(E40:P40),E39/C37),0) -> 0 | R40: =IF(SUM(E40:Q40)<E39,IF((E39-SUM(E40:Q40))<E39/C37,E39-SUM(E40:Q40),E39/C37),0) -> 0 | S40: =IF(SUM(E40:R40)<E39,IF((E39-SUM(E40:R40))<E39/C37,E39-SUM(E40:R40),E39/C37),0) -> 0 | T40: =IF(SUM(E40:S40)<E39,IF((E39-SUM(E40:S40))<E39/C37,E39-SUM(E40:S40),E39/C37),0) -> 0 | U40: =IF(SUM(E40:T40)<E39,IF((E39-SUM(E40:T40))<E39/C37,E39-SUM(E40:T40),E39/C37),0) -> 0 | V40: =IF(SUM(E40:U40)<E39,IF((E39-SUM(E40:U40))<E39/C37,E39-SUM(E40:U40),E39/C37),0) -> 0 | W40: =IF(SUM(E40:V40)<E39,IF((E39-SUM(E40:V40))<E39/C37,E39-SUM(E40:V40),E39/C37),0) -> 0 | X40: =IF(SUM(E40:W40)<E39,IF((E39-SUM(E40:W40))<E39/C37,E39-SUM(E40:W40),E39/C37),0) -> 0
B41: 第二年投资在各年的折旧 | D41: =SUM(E41:X41) -> 0 | F41: =G41*(1-F38/12) -> 0 | G41: =F39/C37 -> 0 | H41: =IF(SUM(E41:G41)<F39,IF((F39-SUM(E41:G41))<F39/C37,F39-SUM(E41:G41),F39/C37),0) -> 0 | I41: =IF(SUM(E41:H41)<F39,IF((F39-SUM(E41:H41))<F39/C37,F39-SUM(E41:H41),F39/C37),0) -> 0 | J41: =IF(SUM(E41:I41)<F39,IF((F39-SUM(E41:I41))<F39/C37,F39-SUM(E41:I41),F39/C37),0) -> 0 | K41: =IF(SUM(E41:J41)<F39,IF((F39-SUM(E41:J41))<F39/C37,F39-SUM(E41:J41),F39/C37),0) -> 0 | L41: =IF(SUM(E41:K41)<F39,IF((F39-SUM(E41:K41))<F39/C37,F39-SUM(E41:K41),F39/C37),0) -> 0 | M41: =IF(SUM(E41:L41)<F39,IF((F39-SUM(E41:L41))<F39/C37,F39-SUM(E41:L41),F39/C37),0) -> 0 | N41: =IF(SUM(E41:M41)<F39,IF((F39-SUM(E41:M41))<F39/C37,F39-SUM(E41:M41),F39/C37),0) -> 0 | O41: =IF(SUM(E41:N41)<F39,IF((F39-SUM(E41:N41))<F39/C37,F39-SUM(E41:N41),F39/C37),0) -> 0 | P41: =IF(SUM(E41:O41)<F39,IF((F39-SUM(E41:O41))<F39/C37,F39-SUM(E41:O41),F39/C37),0) -> 0 | Q41: =IF(SUM(E41:P41)<F39,IF((F39-SUM(E41:P41))<F39/C37,F39-SUM(E41:P41),F39/C37),0) -> 0 | R41: =IF(SUM(E41:Q41)<F39,IF((F39-SUM(E41:Q41))<F39/C37,F39-SUM(E41:Q41),F39/C37),0) -> 0 | S41: =IF(SUM(E41:R41)<F39,IF((F39-SUM(E41:R41))<F39/C37,F39-SUM(E41:R41),F39/C37),0) -> 0 | T41: =IF(SUM(E41:S41)<F39,IF((F39-SUM(E41:S41))<F39/C37,F39-SUM(E41:S41),F39/C37),0) -> 0 | U41: =IF(SUM(E41:T41)<F39,IF((F39-SUM(E41:T41))<F39/C37,F39-SUM(E41:T41),F39/C37),0) -> 0 | V41: =IF(SUM(E41:U41)<F39,IF((F39-SUM(E41:U41))<F39/C37,F39-SUM(E41:U41),F39/C37),0) -> 0 | W41: =IF(SUM(E41:V41)<F39,IF((F39-SUM(E41:V41))<F39/C37,F39-SUM(E41:V41),F39/C37),0) -> 0 | X41: =IF(SUM(E41:W41)<F39,IF((F39-SUM(E41:W41))<F39/C37,F39-SUM(E41:W41),F39/C37),0) -> 0
B42: 第三年投资在各年的折旧 | D42: =SUM(E42:X42) -> 0 | G42: =H42*(1-G38/12) -> 0 | H42: =G39/C37 -> 0 | I42: =IF(SUM(E42:H42)<G39,IF((G39-SUM(E42:H42))<G39/C37,G39-SUM(E42:H42),G39/C37),0) -> 0 | J42: =IF(SUM(E42:I42)<G39,IF((G39-SUM(E42:I42))<G39/C37,G39-SUM(E42:I42),G39/C37),0) -> 0 | K42: =IF(SUM(E42:J42)<G39,IF((G39-SUM(E42:J42))<G39/C37,G39-SUM(E42:J42),G39/C37),0) -> 0 | L42: =IF(SUM(E42:K42)<G39,IF((G39-SUM(E42:K42))<G39/C37,G39-SUM(E42:K42),G39/C37),0) -> 0 | M42: =IF(SUM(E42:L42)<G39,IF((G39-SUM(E42:L42))<G39/C37,G39-SUM(E42:L42),G39/C37),0) -> 0 | N42: =IF(SUM(E42:M42)<G39,IF((G39-SUM(E42:M42))<G39/C37,G39-SUM(E42:M42),G39/C37),0) -> 0 | O42: =IF(SUM(E42:N42)<G39,IF((G39-SUM(E42:N42))<G39/C37,G39-SUM(E42:N42),G39/C37),0) -> 0 | P42: =IF(SUM(E42:O42)<G39,IF((G39-SUM(E42:O42))<G39/C37,G39-SUM(E42:O42),G39/C37),0) -> 0 | Q42: =IF(SUM(E42:P42)<G39,IF((G39-SUM(E42:P42))<G39/C37,G39-SUM(E42:P42),G39/C37),0) -> 0 | R42: =IF(SUM(E42:Q42)<G39,IF((G39-SUM(E42:Q42))<G39/C37,G39-SUM(E42:Q42),G39/C37),0) -> 0 | S42: =IF(SUM(E42:R42)<G39,IF((G39-SUM(E42:R42))<G39/C37,G39-SUM(E42:R42),G39/C37),0) -> 0 | T42: =IF(SUM(E42:S42)<G39,IF((G39-SUM(E42:S42))<G39/C37,G39-SUM(E42:S42),G39/C37),0) -> 0 | U42: =IF(SUM(E42:T42)<G39,IF((G39-SUM(E42:T42))<G39/C37,G39-SUM(E42:T42),G39/C37),0) -> 0 | V42: =IF(SUM(E42:U42)<G39,IF((G39-SUM(E42:U42))<G39/C37,G39-SUM(E42:U42),G39/C37),0) -> 0 | W42: =IF(SUM(E42:V42)<G39,IF((G39-SUM(E42:V42))<G39/C37,G39-SUM(E42:V42),G39/C37),0) -> 0 | X42: =IF(SUM(E42:W42)<G39,IF((G39-SUM(E42:W42))<G39/C37,G39-SUM(E42:W42),G39/C37),0) -> 0
B43: 第四年投资在各年的折旧 | D43: =SUM(E43:X43) -> 0 | H43: =I43*(1-H38/12) -> 0 | I43: =H39/C37 -> 0 | J43: =IF(SUM(E43:I43)<H39,IF((H39-SUM(E43:I43))<H39/C37,H39-SUM(E43:I43),H39/C37),0) -> 0 | K43: =IF(SUM(E43:J43)<H39,IF((H39-SUM(E43:J43))<H39/C37,H39-SUM(E43:J43),H39/C37),0) -> 0 | L43: =IF(SUM(E43:K43)<H39,IF((H39-SUM(E43:K43))<H39/C37,H39-SUM(E43:K43),H39/C37),0) -> 0 | M43: =IF(SUM(E43:L43)<H39,IF((H39-SUM(E43:L43))<H39/C37,H39-SUM(E43:L43),H39/C37),0) -> 0 | N43: =IF(SUM(E43:M43)<H39,IF((H39-SUM(E43:M43))<H39/C37,H39-SUM(E43:M43),H39/C37),0) -> 0 | O43: =IF(SUM(E43:N43)<H39,IF((H39-SUM(E43:N43))<H39/C37,H39-SUM(E43:N43),H39/C37),0) -> 0 | P43: =IF(SUM(E43:O43)<H39,IF((H39-SUM(E43:O43))<H39/C37,H39-SUM(E43:O43),H39/C37),0) -> 0 | Q43: =IF(SUM(E43:P43)<H39,IF((H39-SUM(E43:P43))<H39/C37,H39-SUM(E43:P43),H39/C37),0) -> 0 | R43: =IF(SUM(E43:Q43)<H39,IF((H39-SUM(E43:Q43))<H39/C37,H39-SUM(E43:Q43),H39/C37),0) -> 0 | S43: =IF(SUM(E43:R43)<H39,IF((H39-SUM(E43:R43))<H39/C37,H39-SUM(E43:R43),H39/C37),0) -> 0 | T43: =IF(SUM(E43:S43)<H39,IF((H39-SUM(E43:S43))<H39/C37,H39-SUM(E43:S43),H39/C37),0) -> 0 | U43: =IF(SUM(E43:T43)<H39,IF((H39-SUM(E43:T43))<H39/C37,H39-SUM(E43:T43),H39/C37),0) -> 0 | V43: =IF(SUM(E43:U43)<H39,IF((H39-SUM(E43:U43))<H39/C37,H39-SUM(E43:U43),H39/C37),0) -> 0 | W43: =IF(SUM(E43:V43)<H39,IF((H39-SUM(E43:V43))<H39/C37,H39-SUM(E43:V43),H39/C37),0) -> 0 | X43: =IF(SUM(E43:W43)<H39,IF((H39-SUM(E43:W43))<H39/C37,H39-SUM(E43:W43),H39/C37),0) -> 0
...
